Workbook

Sheet Όμιλοι
A1: ID | B1: Όνομα Ομίλου | C1: Υπεύθυνος | D1: Ημέρα | E1: Σημειώσεις
B2: ← Μπορείτε να αλλάξετε τα ονόματα ομίλων εδώ | E2: ← Προαιρετικές σημειώσεις
A3: C01 | B3: Arduino | D3: Παρασκευή
A4: C02 | B4: CreativeWriting | D4: Τετάρτη
A5: C03 | B5: ECDL | D5: Τρίτη
A6: C04 | B6: Graffiti | D6: Δευτέρα
A7: C05 | B7: I4Good | D7: Δευτέρα
A8: C06 | B8: LEGO | D8: Δευτέρα
A9: C07 | B9: LevelUp | D9: Δευτέρα
A10: C08 | B10: MathBeauty | D10: Παρασκευή
A11: C09 | B11: MediaLab | D11: Πέμπτη
A12: C10 | B12: Shakespeare | D12: Πέμπτη
A13: C11 | B13: Άλγεβρα | C13: Αθανασιάδης | D13: Παρασκευή
A14: C12 | B14: Άλγεβρα | C14: Αριστέρογλου | D14: Τρίτη
A15: C13 | B15: Άλγεβρα | C15: Μπάγκα | D15: Δευτέρα
A16: C14 | B16: Αγγλικά | D16: Δευτέρα
A17: C15 | B17: Αντιγόνη | D17: Τετάρτη
A18: C16 | B18: Αντιγόνη | D18: Πέμπτη
A19: C17 | B19: Αρχαία | C19: Τσεπραηλίδου | D19: Δευτέρα
A20: C18 | B20: Αρχιτεκτονική | D20: Τρίτη
A21: C19 | B21: Αυτοάμυνα | D21: Παρασκευή
A22: C20 | B22: Βιολογία | C22: ενισχυτική | D22: Πέμπτη
A23: C21 | B23: Γαλλικά | D23: Δευτέρα
A24: C22 | B24: Γερμανικά | D24: Δευτέρα
A25: C23 | B25: Γερμανικά | D25: Πέμπτη
A26: C24 | B26: Γλώσσα | C26: Κιτσιούλη | D26: Παρασκευή
A27: C25 | B27: Γλώσσα | C27: Πελεκούδας | D27: Πέμπτη
A28: C26 | B28: Γλώσσα | C28: Τζήμας | D28: Τετάρτη
A29: C27 | B29: Εθελοντισμός | D29: Δευτέρα
A30: C28 | B30: Ευρωπαϊκός Πολιτισμός | D30: Τρίτη
A31: C29 | B31: Ζωγραφική | D31: Τρίτη
A32: C30 | B32: Ιστορία Γ | D32: Τετάρτη
A33: C31 | B33: Καλαθοσφαίριση | D33: Δευτέρα
A34: C32 | B34: Καλαθοσφαίριση | D34: Τετάρτη
A35: C33 | B35: Κινηματογράφος | D35: Τετάρτη
A36: C34 | B36: Κρυπτογραφία | D36: Πέμπτη
A37: C35 | B37: Παραδοσιακός Χορός | C37: Ζαρκοδήμου | D37: Παρασκευή
A38: C36 | B38: Παραδοσιακός Χορός | C38: Κωτούλα | D38: Τρίτη
A39: C37 | B39: Πειραματική_Βιολογία | D39: Τετάρτη
A40: C38 | B40: Πειραματική_Φυσική | D40: Τετάρτη
...

Sheet Οδηγίες
A1: ΟΔΗΓΙΕΣ ΧΡΗΣΗΣ
A3: ΦΥΛΛΟ "Όμιλοι"
A4: • Κάθε γραμμή αντιστοιχεί σε έναν μοναδικό όμιλο.
A5: • Το ID (π.χ. C01) χρησιμοποιείται αυτόματα από την πλατφόρμα — μην το αλλάζετε.
A6: • Αν ο ίδιος καθηγητής κάνει δύο ξεχωριστούς ομίλους (π.χ. Χημεία Τρίτη και Χημεία Τετάρτη), μπαίνουν ως δύο γραμμές.
A7: • Αν ο ίδιος όμιλος γίνεται δύο φορές την εβδομάδα με τους ΙΔΙΟΥΣ μαθητές, μπαίνει ως ΜΙΑ γραμμή.
A9: ΦΥΛΛΟ "Εβδομαδιαία με μαθητές β και γ"
A10: • Δεν αλλάζει τίποτα — συμπληρώνεται ακριβώς όπως πριν.
A11: • Κάθε κελί ημέρας περιέχει το όνομα ομίλου ΑΚΡΙΒΩς όπως στη στήλη "Όνομα Ομίλου" του φύλλου Όμιλοι.
A12: • Αν υπάρχει υπεύθυνος, γράφεται: Όνομα (Υπεύθυνος) — π.χ. "Χημεία (Κυκκίδου)".
A14: ΓΙΑ ΝΕΑ ΧΡΟΝΙΑ
A15: 1. Ενημερώστε το φύλλο Όμιλοι με τους νέους ομίλους (νέα IDs, νέα ονόματα).
... A17: 3. Ανεβάστε το αρχείο στην πλατφόρμα — τα πάντα υπολογίζονται αυτόματα.

Sheet Εβδομαδιαία με μαθητές β και γ
A1: Αριθμός μητρώου | B1: ΕΠΩΝΥΜΟ | C1: ΟΝΟΜΑ | D1: Τάξη | E1: ΤΜΗΜΑ | F1: Δευτέρα | G1: Τρίτη | H1: Τετάρτη | I1: Πέμπτη | J1: Παρασκευή | K1: Βερολίνο
A2: 5597 | B2: ΑΛΕΞΑΝΔΡΟΥ | C2: ΝΙΚΟΛΑΟΣ | D2: Α | E2: Α4 | F2: LevelUp | G2: Ευρωπαϊκός Πολιτισμός | H2: Κινηματογράφος | I2: Κρυπτογραφία | J2: Arduino | K2: Ναι
A3: 5598 | B3: ΑΛΕΞΟΠΟΥΛΟΥ | C3: ΑΝΑΣΤΑΣΙΑ | D3: Α | E3: Α1 | F3: Ψ | G3: Παραδοσιακός Χορός (Κωτούλα) | H3: Αντιγόνη | I3: Αντιγόνη | J3: Φωτογραφία
A4: 5599 | B4: ΑΠΟΣΤΟΛΙΔΟΥ | C4: ΑΛΕΞΑΝΔΡΑ | D4: Α | E4: Α1 | F4: Σύγχρονος_Χορός | G4: Ευρωπαϊκός Πολιτισμός | H4: Χημεία (Κυκκίδου) | I4: ΤΝ | J4: Φωτογραφία | K4: Ναι
A5: 5600 | B5: ΑΡΓΥΡΟΠΟΥΛΟΥ | C5: ΧΡΥΣΟΥΛΑ | D5: Α | E5: Α4 | F5: LevelUp | G5: Άλγεβρα (Αριστέρογλου) | H5: Αντιγόνη | I5: Αντιγόνη | J5: Φυσική (Κασάπη) | K5: Ναι
A6: 5601 | B6: ΑΡΜΕΝΗ | C6: ΠΑΡΑΣΚΕΥΗ | D6: Α | E6: Α4 | F6: I4Good | G6: ECDL | H6: Πειραματική_Βιολογία | I6: Κρυπτογραφία | J6: Παραδοσιακός Χορός (Ζαρκοδήμου) | K6: Ναι
A7: 5602 | B7: ΑΥΞΕΝΤΗ | C7: ΜΑΡΙΑΝΘΗ | D7: Α | E7: Α4 | F7: Εθελοντισμός | G7: Χημεία (Κοντογούνη) | H7: Πειραματική_Βιολογία | I7: Φυσική (Αλεξάνδρου) | J7: Φωτογραφία | K7: Ναι
A8: 5603 | B8: ΒΑΓΓΕΛΑΚΟΣ | C8: ΗΛΙΑΣ | D8: Α | E8: Α4 | F8: Εθελοντισμός | G8: Ποδόσφαιρο | H8: Χημεία (Παπαδοπούλου) | I8: Γερμανικά | J8: Άλγεβρα (Αθανασιάδης) | K8: Ναι
A9: 5604 | B9: ΒΑΝΤΣΙΩΤΗΣ | C9: ΑΝΑΣΤΑΣΙΟΣ | D9: Α | E9: Α4 | F9: LEGO | G9: Άλγεβρα (Αριστέρογλου) | H9: Χημεία (Παπαδοπούλου) | I9: Γερμανικά | J9: Φυσική (Τερλίδης) | K9: Ναι
A10: 5605 | B10: ΒΑΡΣΑΜΗΣ | C10: ΓΕΩΡΓΙΟΣ | D10: Α | E10: Α1 | F10: LEGO | G10: Χημεία (Κοντογούνη) | H10: Κινηματογράφος | I10: Κρυπτογραφία | J10: Arduino | K10: Ναι
A11: 5606 | B11: ΒΡΙΚΟΥ | C11: ΑΙΚΑΤΕΡΙΝΗ-ΕΛΛΗ | D11: Α | E11: Α4 | F11: LevelUp | G11: Ζωγραφική | H11: Αντιγόνη | I11: Αντιγόνη | J11: Ρητορική | K11: Ναι
A12: 5608 | B12: ΓΕΩΡΓΙΑΔΟΥ | C12: ΕΛΕΝΗ | D12: Α | E12: Α4 | F12: Σύγχρονος_Χορός | G12: Ευρωπαϊκός Πολιτισμός | H12: Αντιγόνη | I12: Αντιγόνη | J12: Αυτοάμυνα
A13: 5609 | B13: ΓΚΟΓΚΟΣ | C13: ΗΛΙΑΣ | D13: Α | E13: Α4 | F13: Γερμανικά | G13: Άλγεβρα (Αριστέρογλου) | H13: Χημεία (Παπαδοπούλου) | I13: Κρυπτογραφία | J13: Φυσική (Κασάπη) | K13: Ναι
A14: 5610 | B14: ΓΚΟΝΗΣ | C14: ΑΘΑΝΑΣΙΟΣ | D14: Α | E14: Α4 | F14: I4Good | G14: Ποδόσφαιρο | H14: Αντιγόνη | I14: Αντιγόνη | J14: Άλγεβρα (Αθανασιάδης) | K14: Ναι
A15: 5611 | B15: ΓΚΟΥΜΑΣ | C15: ΓΕΩΡΓΙΟΣ | D15: Α | E15: Α4 | F15: Εθελοντισμός | G15: Ευρωπαϊκός Πολιτισμός | H15: Χημεία (Κοντογούνη) | I15: Φυσική (Αλεξάνδρου) | J15: Arduino | K15: Ναι
A16: 5612 | B16: ΓΟΥΛΑΣ | C16: ΔΗΜΗΤΡΙΟΣ | D16: Α | E16: Α1 | F16: Καλαθοσφαίριση | G16: Χημεία (Κοντογούνη) | H16: Καλαθοσφαίριση | I16: MediaLab | J16: Φυσική (Τερλίδης) | K16: Ναι
A17: 5614 | B17: ΔΕΜΕΡΤΖΙΔΟΥ | C17: ΖΩΗ | D17: Α | E17: Α4 | F17: LEGO | G17: Αρχιτεκτονική | H17: Κινηματογράφος | I17: Χημεία (Κυκκίδου) | J17: Παραδοσιακός Χορός (Ζαρκοδήμου) | K17: Ναι
A18: 5615 | B18: ΔΟΥΒΑΡΤΖΙΔΟΥ | C18: ΣΤΥΛΙΑΝΗ | D18: Α | E18: Α4 | F18: LEGO | G18: Στατιστική | H18: Χημεία (Παπαδοπούλου) | I18: MediaLab | J18: Παραδοσιακός Χορός (Ζαρκοδήμου) | K18: Ναι
A19: 5616 | B19: ΔΟΥΓΑΛΗΣ | C19: ΑΘΑΝΑΣΙΟΣ | D19: Α | E19: Α4 | F19: Άλγεβρα (Μπάγκα) | G19: Χημεία (Κοντογούνη) | H19: Πειραματική_Βιολογία | I19: Φυσική (Αλεξάνδρου) | J19: Αυτοάμυνα | K19: Ναι
A20: 5617 | B20: ΕΥΘΥΒΟΥΛΗ | C20: ΣΤΕΡΓΙΑΝΗ ΧΡΙΣΤΙΝΑ | D20: Α | E20: Α1 | F20: Άλγεβρα (Μπάγκα) | G20: Ευρωπαϊκός Πολιτισμός | H20: Κινηματογράφος | I20: Shakespeare | J20: Παραδοσιακός Χορός (Ζαρκοδήμου)
A21: 5618 | B21: ΖΑΡΟΓΙΑΝΝΗ | C21: ΠΟΛΥΞΕΝΗ | D21: Α | E21: Α4 | F21: I4Good | G21: Ευρωπαϊκός Πολιτισμός | H21: CreativeWriting | I21: Γερμανικά | J21: Παραδοσιακός Χορός (Ζαρκοδήμου) | K21: Ναι
A22: 5619 | B22: ΖΗΚΟΥ | C22: ΣΤΥΛΙΑΝΗ | D22: Α | E22: Α1 | F22: Γαλλικά | G22: Αρχιτεκτονική | H22: Γλώσσα (Τζήμας) | I22: Χημεία (Κυκκίδου) | J22: Φυσική (Τερλίδης) | K22: Ναι
A23: 5620 | B23: ΖΗΣΟΠΟΥΛΟΣ | C23: ΣΤΥΛΙΑΝΟΣ | D23: Α | E23: Α1 | F23: LEGO | G23: ECDL | H23: Αντιγόνη | I23: Αντιγόνη | J23: Arduino | K23: Ναι
A24: 5621 | B24: ΘΕΟΔΩΡΙΔΟΥ | C24: ΕΛΕΝΗ | D24: Α | E24: Α1 | F24: Εθελοντισμός | G24: Ευρωπαϊκός Πολιτισμός | H24: Αντιγόνη | I24: Αντιγόνη | J24: Παραδοσιακός Χορός (Ζαρκοδήμου) | K24: Ναι
A25: 5622 | B25: ΙΩΑΝΝΙΔΗ | C25: ΑΡΓΥΡΗ | D25: Α | E25: Α4 | F25: Graffiti | G25: Παραδοσιακός Χορός (Κωτούλα) | H25: Πειραματική_Βιολογία | I25: Χημεία (Κυκκίδου) | J25: Αυτοάμυνα | K25: Ναι
A26: 5623 | B26: ΙΩΣΗΦΙΔΟΥ | C26: ΑΛΕΞΑΝΔΡΑ | D26: Α | E26: Α4 | F26: Ψ | G26: ECDL | H26: Χημεία (Κυκκίδου) | I26: Γερμανικά | J26: Φυσική (Τερλίδης) | K26: Ναι
A27: 5624 | B27: ΚΑΖΑΝΑ | C27: ΑΝΘΗ-ΖΩΗ | D27: Α | E27: Α1 | F27: Ψ | G27: Ευρωπαϊκός Πολιτισμός | H27: Αντιγόνη | I27: Αντιγόνη | J27: Φωτογραφία
A28: 5625 | B28: ΚΑΖΑΝΤΖΙΔΗΣ | C28: ΕΥΣΤΑΘΙΟΣ | D28: Α | E28: Α4 | F28: Graffiti | G28: Άλγεβρα (Αριστέρογλου) | H28: Αντιγόνη | I28: Αντιγόνη | J28: Φωτογραφία
A29: 5626 | B29: ΚΑΖΑΝΤΖΙΔΟΥ | C29: ΒΑΪΑ | D29: Α | E29: Α4 | F29: Ψ | G29: ECDL | H29: Αντιγόνη | I29: Αντιγόνη | J29: Φωτογραφία
A30: 5627 | B30: ΚΑΖΑΝΤΣΙΔΟΥ | C30: ΔΗΜΗΤΡΑ | D30: Α | E30: Α4 | F30: Εθελοντισμός | G30: Στατιστική | H30: Γλώσσα (Τζήμας) | I30: Γερμανικά | J30: Παραδοσιακός Χορός (Ζαρκοδήμου) | K30: Ναι
A31: 5734 | B31: ΚΑΛΗΜΕΡΗΣ | C31: ΕΥΑΓΓΕΛΟΣ | D31: Α | E31: Α1 | F31: LEGO | G31: Χημεία (Κοντογούνη) | H31: Πληροφορική (Δαρδούμπας) | I31: MediaLab | J31: Arduino | K31: Ναι
A32: 5629 | B32: ΚΑΡΑΒΕΛΙΑ | C32: ΑΝΔΡΟΜΑΧΗ ΑΙΚΑΤΕΡΙΝΗ | D32: Α | E32: Α5 | F32: Graffiti | G32: Ευρωπαϊκός Πολιτισμός | H32: Γλώσσα (Τζήμας) | I32: Κρυπτογραφία | J32: Ρητορική | K32: Ναι
A33: 5630 | B33: ΚΑΡΑΔΗΜΟΣ | C33: ΧΑΡΙΣΙΟΣ | D33: Α | E33: Α1 | F33: LevelUp | G33: Ποδόσφαιρο | H33: Γλώσσα (Τζήμας) | I33: Φυσική (Αλεξάνδρου) | J33: Άλγεβρα (Αθανασιάδης) | K33: Ναι
A34: 5631 | B34: ΚΑΡΑΜΑΝΗΣ | C34: ΛΟΥΚΑΣ | D34: Α | E34: Α1 | F34: LEGO | G34: Αρχιτεκτονική | H34: Πειραματική_Φυσική | I34: Κρυπτογραφία | J34: Arduino | K34: Ναι
A35: 5633 | B35: ΚΑΣΝΑΚΗΣ | C35: ΑΠΟΣΤΟΛΟΣ | D35: Α | E35: Α1 | F35: LEGO | G35: Χημεία (Κοντογούνη) | H35: Πληροφορική (Δαρδούμπας) | I35: Φυσική (Αλεξάνδρου) | J35: Arduino | K35: Ναι
A36: 5634 | B36: ΚΕΪΣΟΓΛΟΥ | C36: ΙΩΑΝΝΗΣ | D36: Α | E36: Α5 | F36: Γερμανικά | G36: Ποδόσφαιρο | H36: Πληροφορική (Δαρδούμπας) | I36: Χημεία (Κυκκίδου) | J36: Φυσική (Τερλίδης) | K36: Ναι
A37: 5635 | B37: ΚΙΖΑΣ | C37: ΒΑΣΙΛΕΙΟΣ | D37: Α | E37: Α5 | F37: Γαλλικά | G37: Ζωγραφική | H37: Χημεία (Κοντογούνη) | I37: Φυσική (Κασάπη) | J37: Αυτοάμυνα | K37: Ναι
A38: 5636 | B38: ΚΛΟΚΙΔΟΥ | C38: ΔΕΣΠΟΙΝΑ | D38: Α | E38: Α1 | F38: Εθελοντισμός | G38: Ζωγραφική | H38: CreativeWriting | I38: ΤΝ | J38: Παραδοσιακός Χορός (Ζαρκοδήμου) | K38: Ναι
A39: 5637 | B39: ΚΟΖΩΝΗΣ | C39: ΕΜΜΑΝΟΥΗΛ | D39: Α | E39: Α1 | F39: Καλαθοσφαίριση | G39: Χημεία (Κοντογούνη) | H39: Καλαθοσφαίριση | I39: Κρυπτογραφία | J39: MathBeauty | K39: Ναι
A40: 5638 | B40: ΚΟΚΚΙΝΙΔΟΥ | C40: ΠΗΝΕΛΟΠΗ | D40: Α | E40: Α1 | F40: Ψ | G40: Άλγεβρα (Αριστέρογλου) | H40: Κινηματογράφος | I40: Ψ2 | J40: Φυσική (Τερλίδης)
...

Sheet Στατιστικά
A1: Ημέρα | B1: Όμιλος | C1: Max θέσεις | D1: Εγγεγραμμένοι | E1: Διαφορά | F1: Υπεράριθμοι; | G1: Παρατηρήσεις | H1: Ενισχυτική | I1: Απουσίες
A2: Δευτέρα | B2: Άλγεβρα (Μπάγκα) | C2: 10 | D2: =COUNTIF('Εβδομαδιαία με μαθητές β και γ'!F:F,B2) | E2: =C2-D2 | F2: =IF(#REF!>C2,1,0) | H2: 1 | I2: 1 | K2: Άλγεβρα | L2: =D2+D16+D51
A3: Δευτέρα | B3: Αρχαία (Τσεπραηλίδου) | C3: 15 | D3: =COUNTIF('Εβδομαδιαία με μαθητές β και γ'!F:F,B3) | E3: =C3-D3 | F3: =IF(#REF!>C3,1,0) | H3: 1 | I3: 1 | K3: Αρχαία | L3: =D3
A4: Δευτέρα | B4: Αγγλικά | C4: 10 | D4: =COUNTIF('Εβδομαδιαία με μαθητές β και γ'!F:F,B4) | E4: =C4-D4 | F4: =IF(#REF!>C4,1,0) | H4: 1 | K4: Αγγλικά Γ' Λυκείου | L4: =D4
A5: Δευτέρα | B5: Γερμανικά | C5: 10 | D5: =COUNTIF('Εβδομαδιαία με μαθητές β και γ'!F:F,B5) | E5: =C5-D5 | F5: =IF(#REF!>C5,1,0) | K5: Χημεία | L5: =D15+D24+D25+D26+D39
A6: Δευτέρα | B6: Καλαθοσφαίριση | C6: 16 | D6: =COUNTIF('Εβδομαδιαία με μαθητές β και γ'!F:F,B6) | E6: =C6-D6 | F6: =IF(#REF!>C6,1,0) | I6: 1 | K6: Γλώσσα | L6: =D27+D38+D50
A7: Δευτέρα | B7: I4Good | C7: 12 | D7: =COUNTIF('Εβδομαδιαία με μαθητές β και γ'!F:F,B7) | E7: =C7-D7 | F7: =IF(#REF!>C7,1,0) | G7: Να ανοίξει στα άλλα σχολεία | I7: 1 | K7: Πληροφορική | L7: =D28
A8: Δευτέρα | B8: Εθελοντισμός | C8: 20 | D8: =COUNTIF('Εβδομαδιαία με μαθητές β και γ'!F:F,B8) | E8: =C8-D8 | F8: =IF(#REF!>C8,1,0) | I8: 1 | K8: Ιστορία Γ' Λυκείου | L8: =D29
A9: Δευτέρα | B9: LevelUp | C9: 15 | D9: =COUNTIF('Εβδομαδιαία με μαθητές β και γ'!F:F,B9) | E9: =C9-D9 | F9: =IF(#REF!>C9,1,0) | I9: 1 | K9: Φυσική | L9: =D36+D37+D48+D49
A10: Δευτέρα | B10: Γαλλικά | C10: 22 | D10: =COUNTIF('Εβδομαδιαία με μαθητές β και γ'!F:F,B10) | E10: =C10-D10 | F10: =IF(#REF!>C10,1,0) | I10: 1 | K10: Βιολογία Β' Λυκείου | L10: =D40
A11: Δευτέρα | B11: Graffiti | C11: 15 | D11: =COUNTIF('Εβδομαδιαία με μαθητές β και γ'!F:F,B11) | E11: =C11-D11 | F11: =IF(#REF!>C11,1,0) | I11: 1
A12: Δευτέρα | B12: Ψ | C12: 12 | D12: =COUNTIF('Εβδομαδιαία με μαθητές β και γ'!F:F,B12) | E12: =C12-D12 | F12: =IF(#REF!>C12,1,0)
A13: Δευτέρα | B13: LEGO | C13: 18 | D13: =COUNTIF('Εβδομαδιαία με μαθητές β και γ'!F:F,B13) | E13: =C13-D13 | F13: =IF(#REF!>C13,1,0) | I13: 1
A14: Δευτέρα | B14: Σύγχρονος_Χορός | C14: 15 | D14: =COUNTIF('Εβδομαδιαία με μαθητές β και γ'!F:F,B14) | E14: =C14-D14 | F14: =IF(#REF!>C14,1,0) | G14: Να ανοίξει στα άλλα σχολεία
A15: Τρίτη | B15: Χημεία (Κοντογούνη) | C15: 10 | D15: =COUNTIF('Εβδομαδιαία με μαθητές β και γ'!G:G,B15) | E15: =C15-D15 | F15: =IF(#REF!>C15,1,0) | H15: 1 | I15: 1
A16: Τρίτη | B16: Άλγεβρα (Αριστέρογλου) | C16: 10 | D16: =COUNTIF('Εβδομαδιαία με μαθητές β και γ'!G:G,B16) | E16: =C16-D16 | F16: =IF(#REF!>C16,1,0) | H16: 1 | I16: 1
A17: Τρίτη | B17: Ποδόσφαιρο | C17: 24 | D17: =COUNTIF('Εβδομαδιαία με μαθητές β και γ'!G:G,B17) | E17: =C17-D17 | F17: =IF(#REF!>C17,1,0) | I17: 1
A18: Τρίτη | B18: Αρχιτεκτονική | C18: 20 | D18: =COUNTIF('Εβδομαδιαία με μαθητές β και γ'!G:G,B18) | E18: =C18-D18 | F18: =IF(#REF!>C18,1,0)
A19: Τρίτη | B19: Στατιστική | C19: 15 | D19: =COUNTIF('Εβδομαδιαία με μαθητές β και γ'!G:G,B19) | E19: =C19-D19 | F19: =IF(#REF!>C19,1,0) | I19: 1
A20: Τρίτη | B20: Παραδοσιακός Χορός (Κωτούλα) | C20: 25 | D20: =COUNTIF('Εβδομαδιαία με μαθητές β και γ'!G:G,B20) | E20: =C20-D20 | F20: =IF(#REF!>C20,1,0)
A21: Τρίτη | B21: Ευρωπαϊκός Πολιτισμός | C21: 15 | D21: =COUNTIF('Εβδομαδιαία με μαθητές β και γ'!G:G,B21) | E21: =C21-D21 | F21: =IF(#REF!>C21,1,0) | I21: 1
A22: Τρίτη | B22: Ζωγραφική | C22: 15 | D22: =COUNTIF('Εβδομαδιαία με μαθητές β και γ'!G:G,B22) | E22: =C22-D22 | F22: =IF(#REF!>C22,1,0)
A23: Τρίτη | B23: ECDL | C23: 14 | D23: =COUNTIF('Εβδομαδιαία με μαθητές β και γ'!G:G,B23) | E23: =C23-D23 | F23: =IF(#REF!>C23,1,0) | I23: 1
A24: Τετάρτη | B24: Χημεία (Κυκκίδου) | C24: 12 | D24: =COUNTIF('Εβδομαδιαία με μαθητές β και γ'!H:H,B24) | E24: =C24-D24 | F24: =IF(#REF!>C24,1,0) | H24: 1 | I24: 1
A25: Τετάρτη | B25: Χημεία (Κοντογούνη) | C25: 12 | D25: =COUNTIF('Εβδομαδιαία με μαθητές β και γ'!H:H,B25) | E25: =C25-D25 | F25: =IF(#REF!>C25,1,0) | H25: 1 | I25: 1
A26: Τετάρτη | B26: Χημεία (Παπαδοπούλου) | C26: 12 | D26: =COUNTIF('Εβδομαδιαία με μαθητές β και γ'!H:H,B26) | E26: =C26-D26 | F26: =IF(#REF!>C26,1,0) | H26: 1 | I26: 1
A27: Τετάρτη | B27: Γλώσσα (Τζήμας) | C27: 12 | D27: =COUNTIF('Εβδομαδιαία με μαθητές β και γ'!H:H,B27) | E27: =C27-D27 | F27: =IF(#REF!>C27,1,0) | H27: 1 | I27: 1
A28: Τετάρτη | B28: Πληροφορική (Δαρδούμπας) | C28: 10 | D28: =COUNTIF('Εβδομαδιαία με μαθητές β και γ'!H:H,B28) | E28: =C28-D28 | F28: =IF(#REF!>C28,1,0) | H28: 1 | I28: 1
A29: Τετάρτη | B29: Ιστορία Γ | C29: 10 | D29: =COUNTIF('Εβδομαδιαία με μαθητές β και γ'!H:H,B29) | E29: =C29-D29 | F29: =IF(#REF!>C29,1,0)
A30: Τετάρτη | B30: Καλαθοσφαίριση | C30: 16 | D30: =COUNTIF('Εβδομαδιαία με μαθητές β και γ'!H:H,B30) | E30: =C30-D30 | F30: =IF(#REF!>C30,1,0) | I30: 1
A31: Τετάρτη | B31: CreativeWriting | C31: 10 | D31: =COUNTIF('Εβδομαδιαία με μαθητές β και γ'!H:H,B31) | E31: =C31-D31 | F31: =IF(#REF!>C31,1,0) | I31: 1
A32: Τετάρτη | B32: Πειραματική_Βιολογία | C32: 12 | D32: =COUNTIF('Εβδομαδιαία με μαθητές β και γ'!H:H,B32) | E32: =C32-D32 | F32: =IF(#REF!>C32,1,0) | I32: 1
A33: Τετάρτη | B33: Πειραματική_Φυσική | C33: 10 | D33: =COUNTIF('Εβδομαδιαία με μαθητές β και γ'!H:H,B33) | E33: =C33-D33 | F33: =IF(#REF!>C33,1,0) | I33: 1
A34: Τετάρτη | B34: Αντιγόνη | C34: 20 | D34: =COUNTIF('Εβδομαδιαία με μαθητές β και γ'!H:H,B34) | E34: =C34-D34 | F34: =IF(#REF!>C34,1,0) | I34: 1
A35: Τετάρτη | B35: Κινηματογράφος | C35: 20 | D35: =COUNTIF('Εβδομαδιαία με μαθητές β και γ'!H:H,B35) | E35: =C35-D35 | F35: =IF(#REF!>C35,1,0) | I35: 1
A36: Πέμπτη | B36: Φυσική (Κασάπη) | C36: 10 | D36: =COUNTIF('Εβδομαδιαία με μαθητές β και γ'!I:I,B36) | E36: =C36-D36 | F36: =IF(#REF!>C36,1,0) | H36: 1
A37: Πέμπτη | B37: Φυσική (Αλεξάνδρου) | C37: 10 | D37: =COUNTIF('Εβδομαδιαία με μαθητές β και γ'!I:I,B37) | E37: =C37-D37 | F37: =IF(#REF!>C37,1,0) | H37: 1
A38: Πέμπτη | B38: Γλώσσα (Πελεκούδας) | C38: 10 | D38: =COUNTIF('Εβδομαδιαία με μαθητές β και γ'!I:I,B38) | E38: =C38-D38 | F38: =IF(#REF!>C38,1,0) | H38: 1 | I38: 1
A39: Πέμπτη | B39: Χημεία (Κυκκίδου) | C39: 10 | D39: =COUNTIF('Εβδομαδιαία με μαθητές β και γ'!I:I,B39) | E39: =C39-D39 | F39: =IF(#REF!>C39,1,0) | H39: 1 | I39: 1
A40: Πέμπτη | B40: Βιολογία (ενισχυτική) | C40: 10 | D40: =COUNTIF('Εβδομαδιαία με μαθητές β και γ'!I:I,B40) | E40: =C40-D40 | F40: =IF(#REF!>C40,1,0) | H40: 1 | I40: 1
...

Sheet Αίθουσες
A1: Ημέρα | B1: Όμιλος | C1: Εκπαιδευτικός | D1: Αίθουσα
A2: Δευτέρα | B2: Άλγεβρα (Μπάγκα) | C2: Μπάγκα Ευφροσύνη | D2: 210
A3: Δευτέρα | B3: Αρχαία (Τσεπραηλίδου) | C3: Τσεπραηλίδου Αγγελική | D3: 308
A4: Δευτέρα | B4: Αγγλικά | C4: Βαγιαννίδου Ελένη - Βαλάσα Ειρήνη | D4: 310
A5: Δευτέρα | B5: Γερμανικά | C5: Βλάχου Αθηνά | D5: 304
A6: Δευτέρα | B6: Καλαθοσφαίριση | C6: Κώτσης Παναγιώτης | D6: 304
A7: Δευτέρα | B7: I4Good | C7: Ευθαλιτσίδου Κυριακή - Τζώτζη Γιαννούλα | D7: 208
A8: Δευτέρα | B8: Εθελοντισμός | C8: Σταμουλά Μαρία-Μαργαρίτα | D8: 311
A9: Δευτέρα | B9: LevelUp | C9: Παπαδοπούλου Γλυκερία | D9: 207
A10: Δευτέρα | B10: Γαλλικά | C10: Γεωργιάδου Αικατερίνη | D10: 313
A11: Δευτέρα | B11: Graffiti | C11: Ματιάκη Χριστίνα | D11: 001
A12: Δευτέρα | B12: Ψ | C12: Βλάχου Κρυστάλλω - Αθανασίου Ελένη | D12: 309
... A57: Παρασκευή | B57: MathBeauty | C57: Αριστέρογλου Ζουμπουλιά | D57: 311

Sheet Πήραν μετεγγραφή
A1: Αριθμός μητρώου | B1: ΕΠΩΝΥΜΟ | C1: ΟΝΟΜΑ | D1: Τάξη | E1: ΤΜΗΜΑ | F1: Δευτέρα | G1: Τρίτη | H1: Τετάρτη | I1: Πέμπτη | J1: Παρασκευή
A2: 5653 | B2: ΚΩΝΣΤΑΝΤΙΝΙΔΗΣ | C2: ΓΑΒΡΙΗΛ | D2: Α | E2: Α2 | F2: Γαλλικά | G2: Στατιστική | H2: Χημεία (Κοντογούνη) | I2: Γλώσσα (Πελεκούδας) | J2: Φυσική (Τερλίδης)
A3: 5679 | B3: ΠΑΠΑΔΟΠΟΥΛΟΥ | C3: ΑΙΚΑΤΕΡΙΝΗ | D3: Α | E3: Α6 | F3: Ψ | G3: Παραδοσιακός_Χορός | H3: CreativeWriting | I3: Ψ2 | J3: Παραδοσιακός_Χορός
A4: 5646 | B4: ΚΟΥΝΤΟΥΡΑΣ | C4: ΝΙΚΟΛΑΟΣ | D4: Α | E4: Α1 | F4: LevelUp | G4: Αρχιτεκτονική | H4: Κινηματογράφος | I4: Κρυπτογραφία | J4: Φωτογραφία
A5: 5607 | B5: ΓΑΡΟΥΦΟΥ | C5: ΓΕΡΑΣΙΜΙΝΑ | D5: Α | E5: Α4 | F5: Graffiti | G5: Ζωγραφική | H5: CreativeWriting | I5: ΤΝ | J5: Arduino
A6: 5613 | B6: ΔΑΛΑΓΙΩΡΓΟΣ | C6: ΚΩΝΣΤΑΝΤΙΝΟΣ | D6: Α | E6: Α1 | F6: I4Good | G6: Ποδόσφαιρο | H6: Χημεία (Κυκκίδου) | I6: Κρυπτογραφία | J6: Αυτοάμυνα
A7: 5738 | B7: ΜΑΡΟΥΔΗΣ | C7: ΓΡΗΓΟΡΙΟΣ | D7: Α | E7: Α1 | F7: LevelUp | G7: Ποδόσφαιρο | H7: Γλώσσα (Τζήμας) | I7: Φυσική (Αλεξάνδρου) | J7: Άλγεβρα (Αθανασιάδης)
